Watching for file changes with StatReloader
[mHTTP GET /playground/hehehey/ 200 [0.03, 127.0.0.1:55937][0m
[mHTTP GET /playground/hello/custom 200 [0.04, 127.0.0.1:55937][0m
/Users/yusprax/Desktop/django-main/webdev/settings.py changed, reloading.
Watching for file changes with StatReloader
Internal Server Error: /playground/hello/big
Traceback (most recent call last):
  File "/Users/yusprax/Desktop/django-main/.venv/lib/python3.9/site-packages/asgiref/sync.py", line 534, in thread_handler
    raise exc_info[1]
  File "/Users/yusprax/Desktop/django-main/.venv/lib/python3.9/site-packages/django/core/handlers/exception.py", line 42, in inner
    response = await get_response(request)
  File "/Users/yusprax/Desktop/django-main/.venv/lib/python3.9/site-packages/django/core/handlers/base.py", line 253, in _get_response_async
    response = await wrapped_callback(
  File "/Users/yusprax/Desktop/django-main/.venv/lib/python3.9/site-packages/asgiref/sync.py", line 479, in __call__
    ret: _R = await loop.run_in_executor(
  File "/Users/yusprax/Desktop/django-main/.venv/lib/python3.9/site-packages/asgiref/current_thread_executor.py", line 40, in run
    result = self.fn(*self.args, **self.kwargs)
  File "/Users/yusprax/Desktop/django-main/.venv/lib/python3.9/site-packages/asgiref/sync.py", line 538, in thread_handler
    return func(*args, **kwargs)
  File "/Users/yusprax/Desktop/django-main/playground/views.py", line 73, in sayBig
    raise Exception({'msg': "This is a simulated exception"})
Exception: {'msg': 'This is a simulated exception'}
Internal Server Error: /playground/hello/big
[35;1mHTTP GET /playground/hello/big 500 [0.10, 127.0.0.1:56763][0m
[mHTTP GET /playground/ 200 [0.02, 127.0.0.1:56763][0m
Watching for file changes with StatReloader
[mHTTP GET / 200 [0.02, 127.0.0.1:61251][0m
[mHTTP GET /playground/ 200 [0.02, 127.0.0.1:61251][0m
[mHTTP GET /playground/error 200 [0.01, 127.0.0.1:61251][0m
